<?xml version="1.0" encoding="UTF-8"?>
<!-- Generated by org.testng.reporters.JUnitXMLReporter -->
<testsuite hostname="sunny-PC" ignored="0" name="这些是测试模块" tests="4" failures="2" timestamp="29 一月 2019 16:46:55 GMT" time="0.111" errors="0">
  <testcase name="test1" time="0.02" classname="com.tesngExtentReport.TestExtentReport">
    <failure type="java.lang.AssertionError" message="expected [2] but found [1]">
      <![CDATA[java.lang.AssertionError: expected [2] but found [1]
	at com.tesngExtentReport.TestExtentReport.test1(TestExtentReport.java:10)
... Removed 30 stack frames]]>
    </failure>
  </testcase> <!-- test1 -->
  <testcase name="test2" time="0.0" classname="com.tesngExtentReport.TestExtentReport"/>
  <testcase name="test3" time="0.0" classname="com.tesngExtentReport.TestExtentReport"/>
  <testcase name="logDemo" time="0.0" classname="com.tesngExtentReport.TestExtentReport">
    <failure type="java.lang.RuntimeException" message="自己写的运行时异常啦！">
      <![CDATA[java.lang.RuntimeException: 自己写的运行时异常啦！
	at com.tesngExtentReport.TestExtentReport.logDemo(TestExtentReport.java:23)
... Removed 24 stack frames]]>
    </failure>
  </testcase> <!-- logDemo -->
</testsuite> <!-- 这些是测试模块 -->
